2025-09-09 13:13:22,028 INFO    MainThread:2753436 [wandb_setup.py:_flush():81] Current SDK version is 0.21.3
2025-09-09 13:13:22,028 INFO    MainThread:2753436 [wandb_setup.py:_flush():81] Configure stats pid to 2753436
2025-09-09 13:13:22,028 INFO    MainThread:2753436 [wandb_setup.py:_flush():81] Loading settings from /home/bl515-ml/.config/wandb/settings
2025-09-09 13:13:22,028 INFO    MainThread:2753436 [wandb_setup.py:_flush():81] Loading settings from /home/bl515-ml/Documents/shaio_jie/ienf_q/wandb/settings
2025-09-09 13:13:22,028 INFO    MainThread:2753436 [wandb_setup.py:_flush():81] Loading settings from environment variables
2025-09-09 13:13:22,028 INFO    MainThread:2753436 [wandb_init.py:setup_run_log_directory():686] Logging user logs to /home/bl515-ml/Documents/shaio_jie/ienf_q/wandb/run-20250909_131322-t6tf5cub/logs/debug.log
2025-09-09 13:13:22,028 INFO    MainThread:2753436 [wandb_init.py:setup_run_log_directory():687] Logging internal logs to /home/bl515-ml/Documents/shaio_jie/ienf_q/wandb/run-20250909_131322-t6tf5cub/logs/debug-internal.log
2025-09-09 13:13:22,028 INFO    MainThread:2753436 [wandb_init.py:init():813] calling init triggers
2025-09-09 13:13:22,028 INFO    MainThread:2753436 [wandb_init.py:init():818] wandb.init called with sweep_config: {}
config: {'num_epochs': 50, 'batch_size': 16, 'learning_rate': 0.001, 'patch_size': 512, 'device': 'cuda', 'architecture': 'NeuralDetectionCNN', 'loss_function': 'SpecialLoss', '_wandb': {}}
2025-09-09 13:13:22,028 INFO    MainThread:2753436 [wandb_init.py:init():854] starting backend
2025-09-09 13:13:22,234 INFO    MainThread:2753436 [wandb_init.py:init():857] sending inform_init request
2025-09-09 13:13:22,241 INFO    MainThread:2753436 [wandb_init.py:init():865] backend started and connected
2025-09-09 13:13:22,243 INFO    MainThread:2753436 [wandb_init.py:init():936] updated telemetry
2025-09-09 13:13:22,252 INFO    MainThread:2753436 [wandb_init.py:init():960] communicating run to backend with 90.0 second timeout
2025-09-09 13:13:22,868 INFO    MainThread:2753436 [wandb_init.py:init():1011] starting run threads in backend
2025-09-09 13:13:22,902 INFO    MainThread:2753436 [wandb_run.py:_console_start():2494] atexit reg
2025-09-09 13:13:22,902 INFO    MainThread:2753436 [wandb_run.py:_redirect():2342] redirect: wrap_raw
2025-09-09 13:13:22,902 INFO    MainThread:2753436 [wandb_run.py:_redirect():2411] Wrapping output streams.
2025-09-09 13:13:22,902 INFO    MainThread:2753436 [wandb_run.py:_redirect():2434] Redirects installed.
2025-09-09 13:13:22,903 INFO    MainThread:2753436 [wandb_init.py:init():1057] run started, returning control to user process
2025-09-09 13:13:23,346 INFO    MainThread:2753436 [wandb_watch.py:_watch():68] Watching
2025-09-09 13:58:30,536 INFO    wandb-AsyncioManager-main:2753436 [service_client.py:_forward_responses():84] Reached EOF.
2025-09-09 13:58:30,536 INFO    wandb-AsyncioManager-main:2753436 [mailbox.py:close():137] Closing mailbox, abandoning 1 handles.
2025-09-09 13:58:30,852 ERROR   wandb-AsyncioManager-main:2753436 [asyncio_manager.py:fn_wrap_exceptions():183] Uncaught exception in run_soon callback.
Traceback (most recent call last):
  File "/home/bl515-ml/Documents/shaio_jie/ienf_q/.venv/lib/python3.12/site-packages/wandb/sdk/lib/asyncio_manager.py", line 181, in fn_wrap_exceptions
    await fn()
  File "/home/bl515-ml/Documents/shaio_jie/ienf_q/.venv/lib/python3.12/site-packages/wandb/sdk/lib/service/service_client.py", line 65, in _send_server_request
    await self._writer.drain()
  File "/home/bl515-ml/.local/share/uv/python/cpython-3.12.11-linux-x86_64-gnu/lib/python3.12/asyncio/streams.py", line 392, in drain
    await self._protocol._drain_helper()
  File "/home/bl515-ml/.local/share/uv/python/cpython-3.12.11-linux-x86_64-gnu/lib/python3.12/asyncio/streams.py", line 166, in _drain_helper
    raise ConnectionResetError('Connection lost')
ConnectionResetError: Connection lost
2025-09-09 13:58:30,856 ERROR   wandb-AsyncioManager-main:2753436 [asyncio_manager.py:fn_wrap_exceptions():183] Uncaught exception in run_soon callback.
Traceback (most recent call last):
  File "/home/bl515-ml/Documents/shaio_jie/ienf_q/.venv/lib/python3.12/site-packages/wandb/sdk/lib/asyncio_manager.py", line 181, in fn_wrap_exceptions
    await fn()
  File "/home/bl515-ml/Documents/shaio_jie/ienf_q/.venv/lib/python3.12/site-packages/wandb/sdk/lib/service/service_client.py", line 65, in _send_server_request
    await self._writer.drain()
  File "/home/bl515-ml/.local/share/uv/python/cpython-3.12.11-linux-x86_64-gnu/lib/python3.12/asyncio/streams.py", line 392, in drain
    await self._protocol._drain_helper()
  File "/home/bl515-ml/.local/share/uv/python/cpython-3.12.11-linux-x86_64-gnu/lib/python3.12/asyncio/streams.py", line 166, in _drain_helper
    raise ConnectionResetError('Connection lost')
ConnectionResetError: Connection lost
2025-09-09 13:58:30,859 ERROR   wandb-AsyncioManager-main:2753436 [asyncio_manager.py:fn_wrap_exceptions():183] Uncaught exception in run_soon callback.
Traceback (most recent call last):
  File "/home/bl515-ml/Documents/shaio_jie/ienf_q/.venv/lib/python3.12/site-packages/wandb/sdk/lib/asyncio_manager.py", line 181, in fn_wrap_exceptions
    await fn()
  File "/home/bl515-ml/Documents/shaio_jie/ienf_q/.venv/lib/python3.12/site-packages/wandb/sdk/lib/service/service_client.py", line 65, in _send_server_request
    await self._writer.drain()
  File "/home/bl515-ml/.local/share/uv/python/cpython-3.12.11-linux-x86_64-gnu/lib/python3.12/asyncio/streams.py", line 392, in drain
    await self._protocol._drain_helper()
  File "/home/bl515-ml/.local/share/uv/python/cpython-3.12.11-linux-x86_64-gnu/lib/python3.12/asyncio/streams.py", line 166, in _drain_helper
    raise ConnectionResetError('Connection lost')
ConnectionResetError: Connection lost
2025-09-09 13:58:30,860 ERROR   wandb-AsyncioManager-main:2753436 [asyncio_manager.py:fn_wrap_exceptions():183] Uncaught exception in run_soon callback.
Traceback (most recent call last):
  File "/home/bl515-ml/Documents/shaio_jie/ienf_q/.venv/lib/python3.12/site-packages/wandb/sdk/lib/asyncio_manager.py", line 181, in fn_wrap_exceptions
    await fn()
  File "/home/bl515-ml/Documents/shaio_jie/ienf_q/.venv/lib/python3.12/site-packages/wandb/sdk/lib/service/service_client.py", line 65, in _send_server_request
    await self._writer.drain()
  File "/home/bl515-ml/.local/share/uv/python/cpython-3.12.11-linux-x86_64-gnu/lib/python3.12/asyncio/streams.py", line 392, in drain
    await self._protocol._drain_helper()
  File "/home/bl515-ml/.local/share/uv/python/cpython-3.12.11-linux-x86_64-gnu/lib/python3.12/asyncio/streams.py", line 166, in _drain_helper
    raise ConnectionResetError('Connection lost')
ConnectionResetError: Connection lost
2025-09-09 13:58:30,861 ERROR   wandb-AsyncioManager-main:2753436 [asyncio_manager.py:fn_wrap_exceptions():183] Uncaught exception in run_soon callback.
Traceback (most recent call last):
  File "/home/bl515-ml/Documents/shaio_jie/ienf_q/.venv/lib/python3.12/site-packages/wandb/sdk/lib/asyncio_manager.py", line 181, in fn_wrap_exceptions
    await fn()
  File "/home/bl515-ml/Documents/shaio_jie/ienf_q/.venv/lib/python3.12/site-packages/wandb/sdk/lib/service/service_client.py", line 65, in _send_server_request
    await self._writer.drain()
  File "/home/bl515-ml/.local/share/uv/python/cpython-3.12.11-linux-x86_64-gnu/lib/python3.12/asyncio/streams.py", line 392, in drain
    await self._protocol._drain_helper()
  File "/home/bl515-ml/.local/share/uv/python/cpython-3.12.11-linux-x86_64-gnu/lib/python3.12/asyncio/streams.py", line 166, in _drain_helper
    raise ConnectionResetError('Connection lost')
ConnectionResetError: Connection lost
2025-09-09 13:58:30,861 ERROR   wandb-AsyncioManager-main:2753436 [asyncio_manager.py:fn_wrap_exceptions():183] Uncaught exception in run_soon callback.
Traceback (most recent call last):
  File "/home/bl515-ml/Documents/shaio_jie/ienf_q/.venv/lib/python3.12/site-packages/wandb/sdk/lib/asyncio_manager.py", line 181, in fn_wrap_exceptions
    await fn()
  File "/home/bl515-ml/Documents/shaio_jie/ienf_q/.venv/lib/python3.12/site-packages/wandb/sdk/lib/service/service_client.py", line 65, in _send_server_request
    await self._writer.drain()
  File "/home/bl515-ml/.local/share/uv/python/cpython-3.12.11-linux-x86_64-gnu/lib/python3.12/asyncio/streams.py", line 392, in drain
    await self._protocol._drain_helper()
  File "/home/bl515-ml/.local/share/uv/python/cpython-3.12.11-linux-x86_64-gnu/lib/python3.12/asyncio/streams.py", line 166, in _drain_helper
    raise ConnectionResetError('Connection lost')
ConnectionResetError: Connection lost
2025-09-09 13:58:30,885 ERROR   wandb-AsyncioManager-main:2753436 [asyncio_manager.py:fn_wrap_exceptions():183] Uncaught exception in run_soon callback.
Traceback (most recent call last):
  File "/home/bl515-ml/Documents/shaio_jie/ienf_q/.venv/lib/python3.12/site-packages/wandb/sdk/lib/asyncio_manager.py", line 181, in fn_wrap_exceptions
    await fn()
  File "/home/bl515-ml/Documents/shaio_jie/ienf_q/.venv/lib/python3.12/site-packages/wandb/sdk/lib/service/service_client.py", line 65, in _send_server_request
    await self._writer.drain()
  File "/home/bl515-ml/.local/share/uv/python/cpython-3.12.11-linux-x86_64-gnu/lib/python3.12/asyncio/streams.py", line 392, in drain
    await self._protocol._drain_helper()
  File "/home/bl515-ml/.local/share/uv/python/cpython-3.12.11-linux-x86_64-gnu/lib/python3.12/asyncio/streams.py", line 166, in _drain_helper
    raise ConnectionResetError('Connection lost')
ConnectionResetError: Connection lost
2025-09-09 13:58:30,886 ERROR   wandb-AsyncioManager-main:2753436 [asyncio_manager.py:fn_wrap_exceptions():183] Uncaught exception in run_soon callback.
Traceback (most recent call last):
  File "/home/bl515-ml/Documents/shaio_jie/ienf_q/.venv/lib/python3.12/site-packages/wandb/sdk/lib/asyncio_manager.py", line 181, in fn_wrap_exceptions
    await fn()
  File "/home/bl515-ml/Documents/shaio_jie/ienf_q/.venv/lib/python3.12/site-packages/wandb/sdk/lib/service/service_client.py", line 65, in _send_server_request
    await self._writer.drain()
  File "/home/bl515-ml/.local/share/uv/python/cpython-3.12.11-linux-x86_64-gnu/lib/python3.12/asyncio/streams.py", line 392, in drain
    await self._protocol._drain_helper()
  File "/home/bl515-ml/.local/share/uv/python/cpython-3.12.11-linux-x86_64-gnu/lib/python3.12/asyncio/streams.py", line 166, in _drain_helper
    raise ConnectionResetError('Connection lost')
ConnectionResetError: Connection lost
2025-09-09 13:58:30,887 ERROR   wandb-AsyncioManager-main:2753436 [asyncio_manager.py:fn_wrap_exceptions():183] Uncaught exception in run_soon callback.
Traceback (most recent call last):
  File "/home/bl515-ml/Documents/shaio_jie/ienf_q/.venv/lib/python3.12/site-packages/wandb/sdk/lib/asyncio_manager.py", line 181, in fn_wrap_exceptions
    await fn()
  File "/home/bl515-ml/Documents/shaio_jie/ienf_q/.venv/lib/python3.12/site-packages/wandb/sdk/lib/service/service_client.py", line 65, in _send_server_request
    await self._writer.drain()
  File "/home/bl515-ml/.local/share/uv/python/cpython-3.12.11-linux-x86_64-gnu/lib/python3.12/asyncio/streams.py", line 392, in drain
    await self._protocol._drain_helper()
  File "/home/bl515-ml/.local/share/uv/python/cpython-3.12.11-linux-x86_64-gnu/lib/python3.12/asyncio/streams.py", line 166, in _drain_helper
    raise ConnectionResetError('Connection lost')
ConnectionResetError: Connection lost
2025-09-09 13:58:30,888 ERROR   wandb-AsyncioManager-main:2753436 [asyncio_manager.py:fn_wrap_exceptions():183] Uncaught exception in run_soon callback.
Traceback (most recent call last):
  File "/home/bl515-ml/Documents/shaio_jie/ienf_q/.venv/lib/python3.12/site-packages/wandb/sdk/lib/asyncio_manager.py", line 181, in fn_wrap_exceptions
    await fn()
  File "/home/bl515-ml/Documents/shaio_jie/ienf_q/.venv/lib/python3.12/site-packages/wandb/sdk/lib/service/service_client.py", line 65, in _send_server_request
    await self._writer.drain()
  File "/home/bl515-ml/.local/share/uv/python/cpython-3.12.11-linux-x86_64-gnu/lib/python3.12/asyncio/streams.py", line 392, in drain
    await self._protocol._drain_helper()
  File "/home/bl515-ml/.local/share/uv/python/cpython-3.12.11-linux-x86_64-gnu/lib/python3.12/asyncio/streams.py", line 166, in _drain_helper
    raise ConnectionResetError('Connection lost')
ConnectionResetError: Connection lost
2025-09-09 13:58:30,891 ERROR   wandb-AsyncioManager-main:2753436 [asyncio_manager.py:fn_wrap_exceptions():183] Uncaught exception in run_soon callback.
Traceback (most recent call last):
  File "/home/bl515-ml/Documents/shaio_jie/ienf_q/.venv/lib/python3.12/site-packages/wandb/sdk/lib/asyncio_manager.py", line 181, in fn_wrap_exceptions
    await fn()
  File "/home/bl515-ml/Documents/shaio_jie/ienf_q/.venv/lib/python3.12/site-packages/wandb/sdk/lib/service/service_client.py", line 65, in _send_server_request
    await self._writer.drain()
  File "/home/bl515-ml/.local/share/uv/python/cpython-3.12.11-linux-x86_64-gnu/lib/python3.12/asyncio/streams.py", line 392, in drain
    await self._protocol._drain_helper()
  File "/home/bl515-ml/.local/share/uv/python/cpython-3.12.11-linux-x86_64-gnu/lib/python3.12/asyncio/streams.py", line 166, in _drain_helper
    raise ConnectionResetError('Connection lost')
ConnectionResetError: Connection lost
